<?xml version="1.0" encoding="UTF-8"?><testsuite name="nosetests" tests="9" errors="1" failures="0" skip="0"><testcase classname="nose.failure.Failure" name="runTest" time="0.000"><error type="exceptions.TypeError" message="data_driven_test() takes exactly 1 argument (0 given)"><![CDATA[Traceback (most recent call last):
  File "/System/Library/Frameworks/Python.framework/Versions/2.7/lib/python2.7/unittest/case.py", line 331, in run
    testMethod()
  File "/Library/Python/2.7/site-packages/nose/loader.py", line 414, in loadTestsFromName
    addr.filename, addr.module)
  File "/Library/Python/2.7/site-packages/nose/importer.py", line 47, in importFromPath
    return self.importFromDir(dir_path, fqname)
  File "/Library/Python/2.7/site-packages/nose/importer.py", line 94, in importFromDir
    mod = load_module(part_fqname, fh, filename, desc)
  File "/Users/egeller/testing/fork/crittercism/tests/signup/new_account_signup.py", line 29, in <module>
    @data_driven_test()
TypeError: data_driven_test() takes exactly 1 argument (0 given)
]]></error></testcase><testcase classname="analytics.AnalyticsTestSuite" name="test_au_version" time="1.764"></testcase><testcase classname="analytics.AnalyticsTestSuite" name="test_todays_affected_users_version" time="1.790"></testcase><testcase classname="analytics.AnalyticsTestSuite" name="test_todays_apploads_crashes_version" time="1.636"></testcase><testcase classname="analytics.AnalyticsTestSuite" name="test_todays_apploads_device" time="1.982"></testcase><testcase classname="analytics.AnalyticsTestSuite" name="test_todays_apploads_version" time="1.699"></testcase><testcase classname="analytics.AnalyticsTestSuite" name="test_todays_crashes_version" time="1.721"></testcase><testcase classname="analytics.AnalyticsTestSuite" name="test_todays_dau_crashes_version" time="1.724"></testcase><testcase classname="analytics.AnalyticsTestSuite" name="test_todays_dau_version" time="1.971"></testcase></testsuite>